#include <stdexcept>

void testException()
{
    throw std::runtime_error("catch me");
}
